Workbook

Sheet Income Statement
A1: Meridian Tech Solutions Ltd - Income Statement
A2: FY2025 by quarter, USD. Synthetic data for testing. Blue = input, black = formula.
A4: Line Item | B4: Q1 2025 | C4: Q2 2025 | D4: Q3 2025 | E4: Q4 2025 | F4: FY 2025
A5: Revenue
A6: Product Revenue | B6: 1200000 | C6: 1350000 | D6: 1420000 | E6: 1580000 | F6: =SUM(B6:E6) -> 5550000
A7: Services Revenue | B7: 400000 | C7: 450000 | D7: 470000 | E7: 520000 | F7: =SUM(B7:E7) -> 1840000
A8: Total Revenue | B8: =SUM(B6:B7) -> 1600000 | C8: =SUM(C6:C7) -> 1800000 | D8: =SUM(D6:D7) -> 1890000 | E8: =SUM(E6:E7) -> 2100000 | F8: =SUM(B8:E8) -> 7390000
A9: Cost of Goods Sold
A10: Cloud Hosting | B10: 210000 | C10: 235000 | D10: 250000 | E10: 275000 | F10: =SUM(B10:E10) -> 970000
A11: Support Costs | B11: 150000 | C11: 165000 | D11: 172000 | E11: 190000 | F11: =SUM(B11:E11) -> 677000
A12: Total COGS | B12: =SUM(B10:B11) -> 360000 | C12: =SUM(C10:C11) -> 400000 | D12: =SUM(D10:D11) -> 422000 | E12: =SUM(E10:E11) -> 465000 | F12: =SUM(B12:E12) -> 1647000
A13: Gross Profit | B13: =B8-B12 -> 1240000 | C13: =C8-C12 -> 1400000 | D13: =D8-D12 -> 1468000 | E13: =E8-E12 -> 1635000 | F13: =SUM(B13:E13) -> 5743000
A14: Operating Expenses
A15: Salaries & Benefits | B15: 620000 | C15: 640000 | D15: 655000 | E15: 680000 | F15: =SUM(B15:E15) -> 2595000
A16: Marketing | B16: 110000 | C16: 150000 | D16: 130000 | E16: 160000 | F16: =SUM(B16:E16) -> 550000
A17: Software & Licenses | B17: 60000 | C17: 78000 | D17: 82000 | E17: 85000 | F17: =SUM(B17:E17) -> 305000
A18: Professional Fees | B18: 40000 | C18: 62000 | D18: 45000 | E18: 55000 | F18: =SUM(B18:E18) -> 202000
A19: Travel & Entertainment | B19: 25000 | C19: 35000 | D19: 30000 | E19: 38000 | F19: =SUM(B19:E19) -> 128000
A20: Rent & Utilities | B20: 60000 | C20: 60000 | D20: 60000 | E20: 60000 | F20: =SUM(B20:E20) -> 240000
A21: Depreciation | B21: 20000 | C21: 20000 | D21: 22000 | E21: 22000 | F21: =SUM(B21:E21) -> 84000
A22: Total Operating Expenses | B22: =SUM(B15:B21) -> 935000 | C22: =SUM(C15:C21) -> 1045000 | D22: =SUM(D15:D21) -> 1024000 | E22: =SUM(E15:E21) -> 1100000 | F22: =SUM(B22:E22) -> 4104000
A23: Operating Income | B23: =B13-B22 -> 305000 | C23: =C13-C22 -> 355000 | D23: =D13-D22 -> 444000 | E23: =E13-E22 -> 535000 | F23: =SUM(B23:E23) -> 1639000
A24: Interest Expense | B24: 15000 | C24: 15000 | D24: 14000 | E24: 14000 | F24: =SUM(B24:E24) -> 58000
A25: Income Before Tax | B25: =B23-B24 -> 290000 | C25: =C23-C24 -> 340000 | D25: =D23-D24 -> 430000 | E25: =E23-E24 -> 521000 | F25: =SUM(B25:E25) -> 1581000
A26: Income Tax | B26: =B25*$B$30 -> 72500 | C26: =C25*$B$30 -> 85000 | D26: =D25*$B$30 -> 107500 | E26: =E25*$B$30 -> 130250 | F26: =SUM(B26:E26) -> 395250
A27: Net Income | B27: =B25-B26 -> 217500 | C27: =C25-C26 -> 255000 | D27: =D25-D26 -> 322500 | E27: =E25-E26 -> 390750 | F27: =SUM(B27:E27) -> 1185750
A29: Assumptions
A30: Income tax rate | B30: 0.25 | C30: Key assumption (hardcoded input); applied to Income Before Tax.

Sheet Balance Sheet
A1: Meridian Tech Solutions Ltd - Balance Sheet
A2: Quarter-end balances, USD. Synthetic data. Blue = input, black = formula, green = link to another sheet.
A4: Line Item | B4: Dec 31, 2024 | C4: Mar 31, 2025 | D4: Jun 30, 2025 | E4: Sep 30, 2025 | F4: Dec 31, 2025
A5: Assets
A6: Cash and Equivalents | B6: 900000 | C6: ='Cash Flow'!B19 -> 1027500 | D6: ='Cash Flow'!C19 -> 1167500 | E6: ='Cash Flow'!D19 -> 1397000 | F6: ='Cash Flow'!E19 -> 1679750
A7: Accounts Receivable | B7: 500000 | C7: 560000 | D7: 635000 | E7: 675000 | F7: 745000
A8: Prepaid Expenses | B8: 60000 | C8: =B8 -> 60000 | D8: =C8 -> 60000 | E8: =D8 -> 60000 | F8: =E8 -> 60000
A9: Property & Equipment, net | B9: 400000 | C9: =B9-'Cash Flow'!B12-'Income Statement'!B21 -> 425000 | D9: =C9-'Cash Flow'!C12-'Income Statement'!C21 -> 465000 | E9: =D9-'Cash Flow'!D12-'Income Statement'!D21 -> 478000 | F9: =E9-'Cash Flow'!E12-'Income Statement'!E21 -> 506000
A10: Total Assets | B10: =SUM(B6:B9) -> 1860000 | C10: =SUM(C6:C9) -> 2072500 | D10: =SUM(D6:D9) -> 2327500 | E10: =SUM(E6:E9) -> 2610000 | F10: =SUM(F6:F9) -> 2990750
A11: Liabilities
A12: Accounts Payable | B12: 180000 | C12: 205000 | D12: 235000 | E12: 225000 | F12: 245000
A13: Accrued Expenses | B13: 90000 | C13: =B13 -> 90000 | D13: =C13 -> 90000 | E13: =D13 -> 90000 | F13: =E13 -> 90000
A14: Term Loan | B14: 600000 | C14: =B14+'Cash Flow'!B15 -> 570000 | D14: =C14+'Cash Flow'!C15 -> 540000 | E14: =D14+'Cash Flow'!D15 -> 510000 | F14: =E14+'Cash Flow'!E15 -> 480000
A15: Total Liabilities | B15: =SUM(B12:B14) -> 870000 | C15: =SUM(C12:C14) -> 865000 | D15: =SUM(D12:D14) -> 865000 | E15: =SUM(E12:E14) -> 825000 | F15: =SUM(F12:F14) -> 815000
A16: Equity
A17: Paid-in Capital | B17: 500000 | C17: =B17 -> 500000 | D17: =C17 -> 500000 | E17: =D17 -> 500000 | F17: =E17 -> 500000
A18: Retained Earnings | B18: 490000 | C18: =B18+'Income Statement'!B27 -> 707500 | D18: =C18+'Income Statement'!C27 -> 962500 | E18: =D18+'Income Statement'!D27 -> 1285000 | F18: =E18+'Income Statement'!E27 -> 1675750
A19: Total Equity | B19: =SUM(B17:B18) -> 990000 | C19: =SUM(C17:C18) -> 1207500 | D19: =SUM(D17:D18) -> 1462500 | E19: =SUM(E17:E18) -> 1785000 | F19: =SUM(F17:F18) -> 2175750
A20: Total Liabilities & Equity | B20: =B15+B19 -> 1860000 | C20: =C15+C19 -> 2072500 | D20: =D15+D19 -> 2327500 | E20: =E15+E19 -> 2610000 | F20: =F15+F19 -> 2990750
A21: Balance Check (Assets - Liabilities - Equity) | B21: =B10-B20 -> 0 | C21: =C10-C20 -> 0 | D21: =D10-D20 -> 0 | E21: =E10-E20 -> 0 | F21: =F10-F20 -> 0

Sheet Cash Flow
A1: Meridian Tech Solutions Ltd - Cash Flow Statement
A2: Indirect method, USD. Synthetic data. Blue = input, black = formula, green = link to another sheet.
A4: Line Item | B4: Q1 2025 | C4: Q2 2025 | D4: Q3 2025 | E4: Q4 2025 | F4: FY 2025
A5: Operating Activities
A6: Net Income | B6: ='Income Statement'!B27 -> 217500 | C6: ='Income Statement'!C27 -> 255000 | D6: ='Income Statement'!D27 -> 322500 | E6: ='Income Statement'!E27 -> 390750 | F6: =SUM(B6:E6) -> 1185750
A7: Depreciation | B7: ='Income Statement'!B21 -> 20000 | C7: ='Income Statement'!C21 -> 20000 | D7: ='Income Statement'!D21 -> 22000 | E7: ='Income Statement'!E21 -> 22000 | F7: =SUM(B7:E7) -> 84000
A8: Change in Accounts Receivable | B8: =-('Balance Sheet'!C7-'Balance Sheet'!B7) -> -60000 | C8: =-('Balance Sheet'!D7-'Balance Sheet'!C7) -> -75000 | D8: =-('Balance Sheet'!E7-'Balance Sheet'!D7) -> -40000 | E8: =-('Balance Sheet'!F7-'Balance Sheet'!E7) -> -70000 | F8: =SUM(B8:E8) -> -245000
A9: Change in Accounts Payable | B9: ='Balance Sheet'!C12-'Balance Sheet'!B12 -> 25000 | C9: ='Balance Sheet'!D12-'Balance Sheet'!C12 -> 30000 | D9: ='Balance Sheet'!E12-'Balance Sheet'!D12 -> -10000 | E9: ='Balance Sheet'!F12-'Balance Sheet'!E12 -> 20000 | F9: =SUM(B9:E9) -> 65000
A10: Net Cash from Operating Activities | B10: =SUM(B6:B9) -> 202500 | C10: =SUM(C6:C9) -> 230000 | D10: =SUM(D6:D9) -> 294500 | E10: =SUM(E6:E9) -> 362750 | F10: =SUM(B10:E10) -> 1089750
A11: Investing Activities
A12: Capital Expenditures | B12: -45000 | C12: -60000 | D12: -35000 | E12: -50000 | F12: =SUM(B12:E12) -> -190000
A13: Net Cash from Investing Activities | B13: =B12 -> -45000 | C13: =C12 -> -60000 | D13: =D12 -> -35000 | E13: =E12 -> -50000 | F13: =SUM(B13:E13) -> -190000
A14: Financing Activities
A15: Term Loan Repayment | B15: -30000 | C15: -30000 | D15: -30000 | E15: -30000 | F15: =SUM(B15:E15) -> -120000
A16: Net Cash from Financing Activities | B16: =B15 -> -30000 | C16: =C15 -> -30000 | D16: =D15 -> -30000 | E16: =E15 -> -30000 | F16: =SUM(B16:E16) -> -120000
A17: Net Change in Cash | B17: =B10+B13+B16 -> 127500 | C17: =C10+C13+C16 -> 140000 | D17: =D10+D13+D16 -> 229500 | E17: =E10+E13+E16 -> 282750 | F17: =SUM(B17:E17) -> 779750
A18: Beginning Cash | B18: ='Balance Sheet'!B6 -> 900000 | C18: =B19 -> 1027500 | D18: =C19 -> 1167500 | E18: =D19 -> 1397000 | F18: =B18 -> 900000
A19: Ending Cash | B19: =B18+B17 -> 1027500 | C19: =C18+C17 -> 1167500 | D19: =D18+D17 -> 1397000 | E19: =E18+E17 -> 1679750 | F19: =E19 -> 1679750

Sheet Budget vs Actual
A1: Meridian Tech Solutions Ltd - Budget vs. Actual by Line Item
A2: Variance = Actual - Budget. For revenue, positive is favorable; for costs, positive means overspend (unfavorable). Synthetic data.
A4: Quarter | B4: Category | C4: Line Item | D4: Budget | E4: Actual | F4: Variance ($) | G4: Variance (%) | H4: Result
A5: Q1 2025 | B5: Revenue | C5: Product Revenue | D5: 1180000 | E5: ='Income Statement'!B6 -> 1200000 | F5: =E5-D5 -> 20000 | G5: =IF(D5=0,0,F5/D5) -> 0.016949153 | H5: =IF(F5=0,"On budget",IF(B5="Revenue",IF(F5>0,"Favorable","Unfavorable"),IF(F5<0,"Favorable","Unfavorable"))) -> Favorable
A6: Q1 2025 | B6: Revenue | C6: Services Revenue | D6: 410000 | E6: ='Income Statement'!B7 -> 400000 | F6: =E6-D6 -> -10000 | G6: =IF(D6=0,0,F6/D6) -> -0.024390244 | H6: =IF(F6=0,"On budget",IF(B6="Revenue",IF(F6>0,"Favorable","Unfavorable"),IF(F6<0,"Favorable","Unfavorable"))) -> Unfavorable
A7: Q1 2025 | B7: Cost of Goods Sold | C7: Cloud Hosting | D7: 205000 | E7: ='Income Statement'!B10 -> 210000 | F7: =E7-D7 -> 5000 | G7: =IF(D7=0,0,F7/D7) -> 0.024390244 | H7: =IF(F7=0,"On budget",IF(B7="Revenue",IF(F7>0,"Favorable","Unfavorable"),IF(F7<0,"Favorable","Unfavorable"))) -> Unfavorable
A8: Q1 2025 | B8: Cost of Goods Sold | C8: Support Costs | D8: 148000 | E8: ='Income Statement'!B11 -> 150000 | F8: =E8-D8 -> 2000 | G8: =IF(D8=0,0,F8/D8) -> 0.013513514 | H8: =IF(F8=0,"On budget",IF(B8="Revenue",IF(F8>0,"Favorable","Unfavorable"),IF(F8<0,"Favorable","Unfavorable"))) -> Unfavorable
A9: Q1 2025 | B9: Operating Expenses | C9: Salaries & Benefits | D9: 615000 | E9: ='Income Statement'!B15 -> 620000 | F9: =E9-D9 -> 5000 | G9: =IF(D9=0,0,F9/D9) -> 0.0081300813 | H9: =IF(F9=0,"On budget",IF(B9="Revenue",IF(F9>0,"Favorable","Unfavorable"),IF(F9<0,"Favorable","Unfavorable"))) -> Unfavorable
A10: Q1 2025 | B10: Operating Expenses | C10: Marketing | D10: 105000 | E10: ='Income Statement'!B16 -> 110000 | F10: =E10-D10 -> 5000 | G10: =IF(D10=0,0,F10/D10) -> 0.047619048 | H10: =IF(F10=0,"On budget",IF(B10="Revenue",IF(F10>0,"Favorable","Unfavorable"),IF(F10<0,"Favorable","Unfavorable"))) -> Unfavorable
A11: Q1 2025 | B11: Operating Expenses | C11: Software & Licenses | D11: 58000 | E11: ='Income Statement'!B17 -> 60000 | F11: =E11-D11 -> 2000 | G11: =IF(D11=0,0,F11/D11) -> 0.034482759 | H11: =IF(F11=0,"On budget",IF(B11="Revenue",IF(F11>0,"Favorable","Unfavorable"),IF(F11<0,"Favorable","Unfavorable"))) -> Unfavorable
A12: Q1 2025 | B12: Operating Expenses | C12: Professional Fees | D12: 38000 | E12: ='Income Statement'!B18 -> 40000 | F12: =E12-D12 -> 2000 | G12: =IF(D12=0,0,F12/D12) -> 0.052631579 | H12: =IF(F12=0,"On budget",IF(B12="Revenue",IF(F12>0,"Favorable","Unfavorable"),IF(F12<0,"Favorable","Unfavorable"))) -> Unfavorable
A13: Q1 2025 | B13: Operating Expenses | C13: Travel & Entertainment | D13: 26000 | E13: ='Income Statement'!B19 -> 25000 | F13: =E13-D13 -> -1000 | G13: =IF(D13=0,0,F13/D13) -> -0.038461538 | H13: =IF(F13=0,"On budget",IF(B13="Revenue",IF(F13>0,"Favorable","Unfavorable"),IF(F13<0,"Favorable","Unfavorable"))) -> Favorable
A14: Q1 2025 | B14: Operating Expenses | C14: Rent & Utilities | D14: 60000 | E14: ='Income Statement'!B20 -> 60000 | F14: =E14-D14 -> 0 | G14: =IF(D14=0,0,F14/D14) -> 0 | H14: =IF(F14=0,"On budget",IF(B14="Revenue",IF(F14>0,"Favorable","Unfavorable"),IF(F14<0,"Favorable","Unfavorable"))) -> On budget
A15: Q1 2025 | B15: Operating Expenses | C15: Depreciation | D15: 20000 | E15: ='Income Statement'!B21 -> 20000 | F15: =E15-D15 -> 0 | G15: =IF(D15=0,0,F15/D15) -> 0 | H15: =IF(F15=0,"On budget",IF(B15="Revenue",IF(F15>0,"Favorable","Unfavorable"),IF(F15<0,"Favorable","Unfavorable"))) -> On budget
A16: Q2 2025 | B16: Revenue | C16: Product Revenue | D16: 1310000 | E16: ='Income Statement'!C6 -> 1350000 | F16: =E16-D16 -> 40000 | G16: =IF(D16=0,0,F16/D16) -> 0.030534351 | H16: =IF(F16=0,"On budget",IF(B16="Revenue",IF(F16>0,"Favorable","Unfavorable"),IF(F16<0,"Favorable","Unfavorable"))) -> Favorable
A17: Q2 2025 | B17: Revenue | C17: Services Revenue | D17: 440000 | E17: ='Income Statement'!C7 -> 450000 | F17: =E17-D17 -> 10000 | G17: =IF(D17=0,0,F17/D17) -> 0.022727273 | H17: =IF(F17=0,"On budget",IF(B17="Revenue",IF(F17>0,"Favorable","Unfavorable"),IF(F17<0,"Favorable","Unfavorable"))) -> Favorable
A18: Q2 2025 | B18: Cost of Goods Sold | C18: Cloud Hosting | D18: 230000 | E18: ='Income Statement'!C10 -> 235000 | F18: =E18-D18 -> 5000 | G18: =IF(D18=0,0,F18/D18) -> 0.02173913 | H18: =IF(F18=0,"On budget",IF(B18="Revenue",IF(F18>0,"Favorable","Unfavorable"),IF(F18<0,"Favorable","Unfavorable"))) -> Unfavorable
A19: Q2 2025 | B19: Cost of Goods Sold | C19: Support Costs | D19: 160000 | E19: ='Income Statement'!C11 -> 165000 | F19: =E19-D19 -> 5000 | G19: =IF(D19=0,0,F19/D19) -> 0.03125 | H19: =IF(F19=0,"On budget",IF(B19="Revenue",IF(F19>0,"Favorable","Unfavorable"),IF(F19<0,"Favorable","Unfavorable"))) -> Unfavorable
A20: Q2 2025 | B20: Operating Expenses | C20: Salaries & Benefits | D20: 650000 | E20: ='Income Statement'!C15 -> 640000 | F20: =E20-D20 -> -10000 | G20: =IF(D20=0,0,F20/D20) -> -0.015384615 | H20: =IF(F20=0,"On budget",IF(B20="Revenue",IF(F20>0,"Favorable","Unfavorable"),IF(F20<0,"Favorable","Unfavorable"))) -> Favorable
A21: Q2 2025 | B21: Operating Expenses | C21: Marketing | D21: 120000 | E21: ='Income Statement'!C16 -> 150000 | F21: =E21-D21 -> 30000 | G21: =IF(D21=0,0,F21/D21) -> 0.25 | H21: =IF(F21=0,"On budget",IF(B21="Revenue",IF(F21>0,"Favorable","Unfavorable"),IF(F21<0,"Favorable","Unfavorable"))) -> Unfavorable
A22: Q2 2025 | B22: Operating Expenses | C22: Software & Licenses | D22: 70000 | E22: ='Income Statement'!C17 -> 78000 | F22: =E22-D22 -> 8000 | G22: =IF(D22=0,0,F22/D22) -> 0.11428571 | H22: =IF(F22=0,"On budget",IF(B22="Revenue",IF(F22>0,"Favorable","Unfavorable"),IF(F22<0,"Favorable","Unfavorable"))) -> Unfavorable
A23: Q2 2025 | B23: Operating Expenses | C23: Professional Fees | D23: 45000 | E23: ='Income Statement'!C18 -> 62000 | F23: =E23-D23 -> 17000 | G23: =IF(D23=0,0,F23/D23) -> 0.37777778 | H23: =IF(F23=0,"On budget",IF(B23="Revenue",IF(F23>0,"Favorable","Unfavorable"),IF(F23<0,"Favorable","Unfavorable"))) -> Unfavorable
A24: Q2 2025 | B24: Operating Expenses | C24: Travel & Entertainment | D24: 30000 | E24: ='Income Statement'!C19 -> 35000 | F24: =E24-D24 -> 5000 | G24: =IF(D24=0,0,F24/D24) -> 0.16666667 | H24: =IF(F24=0,"On budget",IF(B24="Revenue",IF(F24>0,"Favorable","Unfavorable"),IF(F24<0,"Favorable","Unfavorable"))) -> Unfavorable
A25: Q2 2025 | B25: Operating Expenses | C25: Rent & Utilities | D25: 60000 | E25: ='Income Statement'!C20 -> 60000 | F25: =E25-D25 -> 0 | G25: =IF(D25=0,0,F25/D25) -> 0 | H25: =IF(F25=0,"On budget",IF(B25="Revenue",IF(F25>0,"Favorable","Unfavorable"),IF(F25<0,"Favorable","Unfavorable"))) -> On budget
A26: Q2 2025 | B26: Operating Expenses | C26: Depreciation | D26: 20000 | E26: ='Income Statement'!C21 -> 20000 | F26: =E26-D26 -> 0 | G26: =IF(D26=0,0,F26/D26) -> 0 | H26: =IF(F26=0,"On budget",IF(B26="Revenue",IF(F26>0,"Favorable","Unfavorable"),IF(F26<0,"Favorable","Unfavorable"))) -> On budget
A27: Q3 2025 | B27: Revenue | C27: Product Revenue | D27: 1400000 | E27: ='Income Statement'!D6 -> 1420000 | F27: =E27-D27 -> 20000 | G27: =IF(D27=0,0,F27/D27) -> 0.014285714 | H27: =IF(F27=0,"On budget",IF(B27="Revenue",IF(F27>0,"Favorable","Unfavorable"),IF(F27<0,"Favorable","Unfavorable"))) -> Favorable
A28: Q3 2025 | B28: Revenue | C28: Services Revenue | D28: 460000 | E28: ='Income Statement'!D7 -> 470000 | F28: =E28-D28 -> 10000 | G28: =IF(D28=0,0,F28/D28) -> 0.02173913 | H28: =IF(F28=0,"On budget",IF(B28="Revenue",IF(F28>0,"Favorable","Unfavorable"),IF(F28<0,"Favorable","Unfavorable"))) -> Favorable
A29: Q3 2025 | B29: Cost of Goods Sold | C29: Cloud Hosting | D29: 245000 | E29: ='Income Statement'!D10 -> 250000 | F29: =E29-D29 -> 5000 | G29: =IF(D29=0,0,F29/D29) -> 0.020408163 | H29: =IF(F29=0,"On budget",IF(B29="Revenue",IF(F29>0,"Favorable","Unfavorable"),IF(F29<0,"Favorable","Unfavorable"))) -> Unfavorable
A30: Q3 2025 | B30: Cost of Goods Sold | C30: Support Costs | D30: 170000 | E30: ='Income Statement'!D11 -> 172000 | F30: =E30-D30 -> 2000 | G30: =IF(D30=0,0,F30/D30) -> 0.011764706 | H30: =IF(F30=0,"On budget",IF(B30="Revenue",IF(F30>0,"Favorable","Unfavorable"),IF(F30<0,"Favorable","Unfavorable"))) -> Unfavorable
A31: Q3 2025 | B31: Operating Expenses | C31: Salaries & Benefits | D31: 660000 | E31: ='Income Statement'!D15 -> 655000 | F31: =E31-D31 -> -5000 | G31: =IF(D31=0,0,F31/D31) -> -0.0075757576 | H31: =IF(F31=0,"On budget",IF(B31="Revenue",IF(F31>0,"Favorable","Unfavorable"),IF(F31<0,"Favorable","Unfavorable"))) -> Favorable
A32: Q3 2025 | B32: Operating Expenses | C32: Marketing | D32: 135000 | E32: ='Income Statement'!D16 -> 130000 | F32: =E32-D32 -> -5000 | G32: =IF(D32=0,0,F32/D32) -> -0.037037037 | H32: =IF(F32=0,"On budget",IF(B32="Revenue",IF(F32>0,"Favorable","Unfavorable"),IF(F32<0,"Favorable","Unfavorable"))) -> Favorable
A33: Q3 2025 | B33: Operating Expenses | C33: Software & Licenses | D33: 80000 | E33: ='Income Statement'!D17 -> 82000 | F33: =E33-D33 -> 2000 | G33: =IF(D33=0,0,F33/D33) -> 0.025 | H33: =IF(F33=0,"On budget",IF(B33="Revenue",IF(F33>0,"Favorable","Unfavorable"),IF(F33<0,"Favorable","Unfavorable"))) -> Unfavorable
A34: Q3 2025 | B34: Operating Expenses | C34: Professional Fees | D34: 50000 | E34: ='Income Statement'!D18 -> 45000 | F34: =E34-D34 -> -5000 | G34: =IF(D34=0,0,F34/D34) -> -0.1 | H34: =IF(F34=0,"On budget",IF(B34="Revenue",IF(F34>0,"Favorable","Unfavorable"),IF(F34<0,"Favorable","Unfavorable"))) -> Favorable
A35: Q3 2025 | B35: Operating Expenses | C35: Travel & Entertainment | D35: 32000 | E35: ='Income Statement'!D19 -> 30000 | F35: =E35-D35 -> -2000 | G35: =IF(D35=0,0,F35/D35) -> -0.0625 | H35: =IF(F35=0,"On budget",IF(B35="Revenue",IF(F35>0,"Favorable","Unfavorable"),IF(F35<0,"Favorable","Unfavorable"))) -> Favorable
A36: Q3 2025 | B36: Operating Expenses | C36: Rent & Utilities | D36: 60000 | E36: ='Income Statement'!D20 -> 60000 | F36: =E36-D36 -> 0 | G36: =IF(D36=0,0,F36/D36) -> 0 | H36: =IF(F36=0,"On budget",IF(B36="Revenue",IF(F36>0,"Favorable","Unfavorable"),IF(F36<0,"Favorable","Unfavorable"))) -> On budget
A37: Q3 2025 | B37: Operating Expenses | C37: Depreciation | D37: 22000 | E37: ='Income Statement'!D21 -> 22000 | F37: =E37-D37 -> 0 | G37: =IF(D37=0,0,F37/D37) -> 0 | H37: =IF(F37=0,"On budget",IF(B37="Revenue",IF(F37>0,"Favorable","Unfavorable"),IF(F37<0,"Favorable","Unfavorable"))) -> On budget
A38: Q4 2025 | B38: Revenue | C38: Product Revenue | D38: 1545000 | E38: ='Income Statement'!E6 -> 1580000 | F38: =E38-D38 -> 35000 | G38: =IF(D38=0,0,F38/D38) -> 0.022653722 | H38: =IF(F38=0,"On budget",IF(B38="Revenue",IF(F38>0,"Favorable","Unfavorable"),IF(F38<0,"Favorable","Unfavorable"))) -> Favorable
A39: Q4 2025 | B39: Revenue | C39: Services Revenue | D39: 510000 | E39: ='Income Statement'!E7 -> 520000 | F39: =E39-D39 -> 10000 | G39: =IF(D39=0,0,F39/D39) -> 0.019607843 | H39: =IF(F39=0,"On budget",IF(B39="Revenue",IF(F39>0,"Favorable","Unfavorable"),IF(F39<0,"Favorable","Unfavorable"))) -> Favorable
A40: Q4 2025 | B40: Cost of Goods Sold | C40: Cloud Hosting | D40: 270000 | E40: ='Income Statement'!E10 -> 275000 | F40: =E40-D40 -> 5000 | G40: =IF(D40=0,0,F40/D40) -> 0.018518519 | H40: =IF(F40=0,"On budget",IF(B40="Revenue",IF(F40>0,"Favorable","Unfavorable"),IF(F40<0,"Favorable","Unfavorable"))) -> Unfavorable
A41: Q4 2025 | B41: Cost of Goods Sold | C41: Support Costs | D41: 185000 | E41: ='Income Statement'!E11 -> 190000 | F41: =E41-D41 -> 5000 | G41: =IF(D41=0,0,F41/D41) -> 0.027027027 | H41: =IF(F41=0,"On budget",IF(B41="Revenue",IF(F41>0,"Favorable","Unfavorable"),IF(F41<0,"Favorable","Unfavorable"))) -> Unfavorable
...
